<?xml version="1.0" encoding="utf-8"?>
<robot xmlns:xacro="http://www.ros.org/wiki/xacro" name="myrobot">

  <xacro:macro name="myrobot" params="arm_id:='myrobot' package_name:='myrobot_description' connected_to:='' xyz:='0 0 0' rpy:='0 0 0' hardware_interface:=''">
    <xacro:unless value="${not connected_to}">
      <link name="${connected_to}"/>
      <joint name="${arm_id}_joint_${connected_to}" type="fixed">
        <parent link="${connected_to}"/>
        <child link="${arm_id}_link1"/>
        <origin rpy="${rpy}" xyz="${xyz}"/>
      </joint>
    </xacro:unless>

    <xacro:property name="PI" value="3.1415926535897931"/>

    <!-- Base Link -->
    <link name="${arm_id}_link1">
      <collision>
        <origin xyz="0 0 0" rpy="0 0 0"/>
        <geometry>
          <mesh filename="package://myrobot_description/meshes/Base.stl"/>
        </geometry>
      </collision>

      <visual>
        <origin xyz="0 0 0" rpy="0 0 0"/>
        <geometry>
          <mesh filename="package://myrobot_description/meshes/Base.stl"/>
        </geometry>
        <material name="">
          <color rgba="1 1 1 1"/>
        </material>
      </visual>

      <inertial>
        <origin xyz="0 0 0" rpy="0 0 0"/>
        <mass value="1.0"/>
        <inertia ixx="1" ixy="0" ixz="1" iyy="0" iyz="1" izz="0"/>
      </inertial> 
    </link>

    <joint name="${arm_id}_joint1" type="continuous">
      <parent link="${arm_id}_link1"/>
      <child link="${arm_id}_link2"/>
      <origin xyz="0 0 0.07" rpy="0 0 0"/>
      <axis xyz="0 0 1"/>
      <dynamics damping="0.1"/>
    </joint>

    <link name="${arm_id}_link2">
      <collision>
        <origin xyz="0 0 0" rpy="0 0 0"/>
        <geometry>
          <mesh filename="package://myrobot_description/meshes/Link1.stl"/>
        </geometry>
      </collision>

      <visual>
        <origin xyz="0 0 0" rpy="0 0 0"/>
        <geometry>
          <mesh filename="package://myrobot_description/meshes/Link1.stl"/>
        </geometry>
        <material name="">
          <color rgba="1 1 1 1"/>
        </material>
      </visual>

      <inertial>
        <origin xyz="0 0 0" rpy="0 0 0"/>
        <mass value="2.75458"/>
        <inertia ixx="0.0109697" ixy="-2.08287e-08" ixz="-0.000398309" iyy="0.011856" iyz="2.03974e-09" izz="0.00604953"/>
      </inertial>
    </link>

    <joint name="${arm_id}_joint2" type="continuous">
      <parent link="${arm_id}_link2"/>
      <child link="${arm_id}_link3"/>
      <origin xyz="0.08 0 0.12" rpy="${pi/2} 0 ${pi/2}"/>
      <axis xyz="0 0 1"/>
      <dynamics damping="0.1"/>
    </joint>

    <link name="${arm_id}_link3">
      <collision>
        <origin xyz="0 0 0" rpy="0 0 0"/>
        <geometry>
          <mesh filename="package://myrobot_description/meshes/Link2.stl"/>
        </geometry>
      </collision>

      <visual>
        <origin xyz="0 0 0" rpy="0 0 0"/>
        <geometry>
          <mesh filename="package://myrobot_description/meshes/Link2.stl"/>
        </geometry>
        <material name="">
          <color rgba="1 1 1 1"/>
        </material>
      </visual>

      <inertial>
        <origin xyz="0 0 0" rpy="0 0 0"/>
        <mass value="8.143"/>
        <inertia ixx="0.25374" ixy="1.41285e-07" ixz="-7.13886e-08" iyy="0.0212824" iyz="0.00499483" izz="0.247523"/>
      </inertial>
    </link>

    <joint name="${arm_id}_joint3" type="continuous">
      <parent link="${arm_id}_link3"/>
      <child link="${arm_id}_link4"/>
      <origin xyz="0 0.43 0" rpy="0 0 0"/>
      <axis xyz="0 0 1"/>
      <dynamics damping="0.1"/>
    </joint>

    <link name="${arm_id}_link4">
      <collision>
        <origin xyz="0 0 0" rpy="0 0 0"/>
        <geometry>
          <mesh filename="package://myrobot_description/meshes/Link3.stl"/>
        </geometry>
      </collision>

      <visual>
        <origin xyz="0 0 0" rpy="0 0 0"/>
        <geometry>
          <mesh filename="package://myrobot_description/meshes/Link3.stl"/>
        </geometry>
        <material name="">
          <color rgba="1 1 1 1"/>
        </material>
      </visual>

      <inertial>
        <origin xyz="0 0 0" rpy="0 0 0"/>
        <mass value="5.14886"/>
        <inertia ixx="0.075434" ixy="2.67415e-08" ixz="2.13561e-09" iyy="0.010425" iyz="0.00274946" izz="0.0744749"/>
      </inertial>
    </link>

    <!-- GAZEBO -->
    <xacro:arg name="gazebo" default="true"/>
    <xacro:arg name="hardware_interface" default="EffortJointInterface"/>
    <gazebo>
      <plugin name="gazebo_ros_control" filename="libgazebo_ros_control.so">
        <!-- <robotNamespace>/</robotNamespace> -->
        <robotNamespace>${arm_id}</robotNamespace>
      </plugin>
    </gazebo>

    <gazebo reference="${arm_id}_link1">
      <turnGravityOff>false</turnGravityOff>
    </gazebo>
    <gazebo reference="${arm_id}_link2">
      <turnGravityOff>false</turnGravityOff>
    </gazebo>
    <gazebo reference="${arm_id}_link3">
      <turnGravityOff>false</turnGravityOff>
    </gazebo>
    <gazebo reference="${arm_id}_link4">
      <turnGravityOff>false</turnGravityOff>
    </gazebo>

    <transmission name="${arm_id}_joint1_trans">
      <type>transmission_interface/SimpleTransmission</type>
      <joint name="${arm_id}_joint1">
        <hardwareInterface>hardware_interface/EffortJointInterface</hardwareInterface>
      </joint>
      <actuator name="${arm_id}_joint1_motor">
        <hardwareInterface>hardware_interface/EffortJointInterface</hardwareInterface>
        <mechanicalReduction>1</mechanicalReduction>
      </actuator>
    </transmission>

    <transmission name="${arm_id}_joint2_trans">
      <type>transmission_interface/SimpleTransmission</type>
      <joint name="${arm_id}_joint2">
        <hardwareInterface>hardware_interface/EffortJointInterface</hardwareInterface>
      </joint>
      <actuator name="${arm_id}_joint2_motor">
        <hardwareInterface>hardware_interface/EffortJointInterface</hardwareInterface>
        <mechanicalReduction>1</mechanicalReduction>
      </actuator>
    </transmission>

    <transmission name="${arm_id}_joint3_trans">
      <type>transmission_interface/SimpleTransmission</type>
      <joint name="${arm_id}_joint3">
        <hardwareInterface>hardware_interface/EffortJointInterface</hardwareInterface>
      </joint>
      <actuator name="${arm_id}_joint3_motor">
        <hardwareInterface>hardware_interface/EffortJointInterface</hardwareInterface>
        <mechanicalReduction>1</mechanicalReduction>
      </actuator>
    </transmission>



  </xacro:macro>

</robot>

